Workbook

Sheet Cover
A1: MPP MES — Factory Acceptance Test (FAT)
A2: Madison Precision Products, Inc. · Blue Ridge Automation
A4: Measured against | B4: MPP MES Functional Design Specification (FDS) — FRS crosswalk shown per requirement
A5: Scope | B5: Full MVP / MVP-EXPANDED — Config Tool (Arc 1) + Plant Floor (Arc 2)
A6: FDS requirements | B6: 226 in-scope · 9 conditional · 7 out-of-scope (see Coverage sheet)
A7: Total test steps | B7: 367
A8: In-scope requirements with no test | B8: 0
A10: ENVIRONMENT UNDER TEST (fill in at witnessing)
A11: Ignition Gateway version
A12: SQL Server / database
A13: Git commit / build tag
A14: Test date(s)
A16: SIGN-OFF
A17: Role | B17: Name | D17: Signature | E17: Date
A18: MPP — Acceptance
A19: MPP — Quality
A20: Blue Ridge — Lead
A22: ROLL-UP (live — updates as Result cells are filled)
A23: Area | B23: Total | C23: Pass | D23: Fail | E23: N/A | F23: Open
A24: Environment & Platform | B24: 27 | C24: =COUNTIF('Environment & Platform'!F:F,"Pass") | D24: =COUNTIF('Environment & Platform'!F:F,"Fail") | E24: =COUNTIF('Environment & Platform'!F:F,"N/A") | F24: =B24-C24-D24-E24
A25: Plant Hierarchy | B25: 14 | C25: =COUNTIF('Plant Hierarchy'!F:F,"Pass") | D25: =COUNTIF('Plant Hierarchy'!F:F,"Fail") | E25: =COUNTIF('Plant Hierarchy'!F:F,"N/A") | F25: =B25-C25-D25-E25
A26: Item Master | B26: 8 | C26: =COUNTIF('Item Master'!F:F,"Pass") | D26: =COUNTIF('Item Master'!F:F,"Fail") | E26: =COUNTIF('Item Master'!F:F,"N/A") | F26: =B26-C26-D26-E26
A27: Routes & BOMs | B27: 12 | C27: =COUNTIF('Routes & BOMs'!F:F,"Pass") | D27: =COUNTIF('Routes & BOMs'!F:F,"Fail") | E27: =COUNTIF('Routes & BOMs'!F:F,"N/A") | F27: =B27-C27-D27-E27
A28: Op Templates & Quality Specs | B28: 9 | C28: =COUNTIF('Op Templates & Quality Specs'!F:F,"Pass") | D28: =COUNTIF('Op Templates & Quality Specs'!F:F,"Fail") | E28: =COUNTIF('Op Templates & Quality Specs'!F:F,"N/A") | F28: =B28-C28-D28-E28
A29: Container Configs | B29: 7 | C29: =COUNTIF('Container Configs'!F:F,"Pass") | D29: =COUNTIF('Container Configs'!F:F,"Fail") | E29: =COUNTIF('Container Configs'!F:F,"N/A") | F29: =B29-C29-D29-E29
A30: Code Tables | B30: 10 | C30: =COUNTIF('Code Tables'!F:F,"Pass") | D30: =COUNTIF('Code Tables'!F:F,"Fail") | E30: =COUNTIF('Code Tables'!F:F,"N/A") | F30: =B30-C30-D30-E30
A31: Shift Schedules | B31: 8 | C31: =COUNTIF('Shift Schedules'!F:F,"Pass") | D31: =COUNTIF('Shift Schedules'!F:F,"Fail") | E31: =COUNTIF('Shift Schedules'!F:F,"N/A") | F31: =B31-C31-D31-E31
A32: PLC Device Mapping | B32: 23 | C32: =COUNTIF('PLC Device Mapping'!F:F,"Pass") | D32: =COUNTIF('PLC Device Mapping'!F:F,"Fail") | E32: =COUNTIF('PLC Device Mapping'!F:F,"N/A") | F32: =B32-C32-D32-E32
A33: Users & Attribution | B33: 19 | C33: =COUNTIF('Users & Attribution'!F:F,"Pass") | D33: =COUNTIF('Users & Attribution'!F:F,"Fail") | E33: =COUNTIF('Users & Attribution'!F:F,"N/A") | F33: =B33-C33-D33-E33
A34: Terminal & Login | B34: 16 | C34: =COUNTIF('Terminal & Login'!F:F,"Pass") | D34: =COUNTIF('Terminal & Login'!F:F,"Fail") | E34: =COUNTIF('Terminal & Login'!F:F,"N/A") | F34: =B34-C34-D34-E34
A35: Die Cast | B35: 20 | C35: =COUNTIF('Die Cast'!F:F,"Pass") | D35: =COUNTIF('Die Cast'!F:F,"Fail") | E35: =COUNTIF('Die Cast'!F:F,"N/A") | F35: =B35-C35-D35-E35
A36: Trim | B36: 9 | C36: =COUNTIF('Trim'!F:F,"Pass") | D36: =COUNTIF('Trim'!F:F,"Fail") | E36: =COUNTIF('Trim'!F:F,"N/A") | F36: =B36-C36-D36-E36
A37: Machining | B37: 20 | C37: =COUNTIF('Machining'!F:F,"Pass") | D37: =COUNTIF('Machining'!F:F,"Fail") | E37: =COUNTIF('Machining'!F:F,"N/A") | F37: =B37-C37-D37-E37
A38: Assembly | B38: 24 | C38: =COUNTIF('Assembly'!F:F,"Pass") | D38: =COUNTIF('Assembly'!F:F,"Fail") | E38: =COUNTIF('Assembly'!F:F,"N/A") | F38: =B38-C38-D38-E38
A39: Third-Party Inspection | B39: 4 | C39: =COUNTIF('Third-Party Inspection'!F:F,"Pass") | D39: =COUNTIF('Third-Party Inspection'!F:F,"Fail") | E39: =COUNTIF('Third-Party Inspection'!F:F,"N/A") | F39: =B39-C39-D39-E39
A40: Quality Capture & Holds | B40: 25 | C40: =COUNTIF('Quality Capture & Holds'!F:F,"Pass") | D40: =COUNTIF('Quality Capture & Holds'!F:F,"Fail") | E40: =COUNTIF('Quality Capture & Holds'!F:F,"N/A") | F40: =B40-C40-D40-E40
A41: Movements & Inventory | B41: 22 | C41: =COUNTIF('Movements & Inventory'!F:F,"Pass") | D41: =COUNTIF('Movements & Inventory'!F:F,"Fail") | E41: =COUNTIF('Movements & Inventory'!F:F,"N/A") | F41: =B41-C41-D41-E41
A42: LOT Traceability & Genealogy | B42: 35 | C42: =COUNTIF('LOT Traceability & Genealogy'!F:F,"Pass") | D42: =COUNTIF('LOT Traceability & Genealogy'!F:F,"Fail") | E42: =COUNTIF('LOT Traceability & Genealogy'!F:F,"N/A") | F42: =B42-C42-D42-E42
A43: Shift & Downtime | B43: 23 | C43: =COUNTIF('Shift & Downtime'!F:F,"Pass") | D43: =COUNTIF('Shift & Downtime'!F:F,"Fail") | E43: =COUNTIF('Shift & Downtime'!F:F,"N/A") | F43: =B43-C43-D43-E43
A44: Labels & Printing | B44: 18 | C44: =COUNTIF('Labels & Printing'!F:F,"Pass") | D44: =COUNTIF('Labels & Printing'!F:F,"Fail") | E44: =COUNTIF('Labels & Printing'!F:F,"N/A") | F44: =B44-C44-D44-E44
...

Sheet Coverage
A1: FDS | B1: Title | C1: Section | D1: Area | E1: Scope | F1: FRS crosswalk | G1: Covering TestIDs | H1: Coverage
A2: FDS-01-001 | B2: Ignition Gateway | C2: 1.2 System Topology | D2: Environment & Platform | E2: MVP | G2: FAT-ENV-010, FAT-ENV-020 | H2: Covered (2)
A3: FDS-01-002 | B3: Database Server | C3: 1.2 System Topology | D3: Environment & Platform | E3: MVP | G3: FAT-ENV-030 | H3: Covered (1)
A4: FDS-01-003 | B4: Redundancy | C4: 1.2 System Topology | D4: Environment & Platform | E4: MVP | G4: FAT-ENV-040 | H4: Covered (1)
A5: FDS-01-004 | B5: Development/Test Environment | C5: 1.2 System Topology | D5: Environment & Platform | E5: MVP | G5: FAT-ENV-050 | H5: Covered (1)
A6: FDS-01-005 | B6: Event Immutability | C6: 1.4 Data Flow Architecture | D6: Environment & Platform | E6: MVP | F6: 3.5.4, 3.9.6 | G6: FAT-ENV-060 | H6: Covered (1)
A7: FDS-01-006 | B7: External Interface Dispatch Pattern | C7: 1.4 Data Flow Architecture | D7: Environment & Platform | E7: MVP | F7: 3.17.4, 5.5.1 | G7: FAT-ENV-070 | H7: Covered (1)
A8: FDS-01-007 | B8: Tag Historian Separation | C8: 1.4 Data Flow Architecture | D8: Environment & Platform | E8: MVP | F8: 3.4.10, 5.5.1 | G8: FAT-ENV-080 | H8: Covered (1)
A9: FDS-01-013 | B9: BOM Source System at Cutover | C9: 1.4 Data Flow Architecture | D9: Environment & Platform | E9: MVP | G9: FAT-ENV-090, FAT-ENV-100 | H9: Covered (2)
A10: FDS-01-008 | B10: OPC Server Connections | C10: 1.5 OPC Connection Architecture | D10: Environment & Platform | E10: MVP | G10: FAT-ENV-110 | H10: Covered (1)
A11: FDS-01-009 | B11: OPC Tag Namespace | C11: 1.5 OPC Connection Architecture | D11: Environment & Platform | E11: MVP | G11: FAT-ENV-120 | H11: Covered (1)
A12: FDS-01-010 | B12: Authentication | C12: 1.6 Security Architecture | D12: Environment & Platform | E12: MVP | F12: 5.3 | G12: FAT-ENV-130, FAT-ENV-140 | H12: Covered (2)
A13: FDS-01-011 | B13: Authorization | C13: 1.6 Security Architecture | D13: Environment & Platform | E13: MVP | G13: FAT-ENV-150 | H13: Covered (1)
A14: FDS-01-012 | B14: Audit Attribution | C14: 1.6 Security Architecture | D14: Environment & Platform | E14: MVP | G14: FAT-ENV-160 | H14: Covered (1)
A15: FDS-01-014 | B15: External Integration Pattern (Gateway-script-async) | C15: 1.6 Security Architecture | D15: Environment & Platform | E15: MVP | G15: FAT-ENV-170, FAT-ENV-180 | H15: Covered (2)
A16: FDS-02-001 | B16: ISA-95 Location Types | C16: 2.2 Location Type Hierarchy | D16: Plant Hierarchy | E16: MVP | G16: FAT-PH-010, FAT-PH-020 | H16: Covered (2)
A17: FDS-02-002 | B17: Hierarchy Enforcement | C17: 2.2 Location Type Hierarchy | D17: Plant Hierarchy | E17: MVP | G17: FAT-PH-030, FAT-PH-040 | H17: Covered (2)
A18: FDS-02-003 | B18: Areas as Instances | C18: 2.2 Location Type Hierarchy | D18: Plant Hierarchy | E18: MVP | F18: 3.3.2, 3.7.1 | G18: FAT-PH-050 | H18: Covered (1)
A19: FDS-02-004 | B19: Location Type Definitions (Kinds) | C19: 2.3 Polymorphic Kinds and Configurable Attributes | D19: Plant Hierarchy | E19: MVP | G19: FAT-PH-060, FAT-PH-070 | H19: Covered (2)
A20: FDS-02-005 | B20: Attribute Schemas per Definition | C20: 2.3 Polymorphic Kinds and Configurable Attributes | D20: Plant Hierarchy | E20: MVP | G20: FAT-PH-080 | H20: Covered (1)
A21: FDS-02-006 | B21: Attribute Value Integrity | C21: 2.3 Polymorphic Kinds and Configurable Attributes | D21: Plant Hierarchy | E21: MVP | G21: FAT-PH-090 | H21: Covered (1)
A22: FDS-02-007 | B22: Machine Seed Data | C22: 2.4 Seed Data | D22: Plant Hierarchy | E22: MVP | G22: FAT-PH-100 | H22: Covered (1)
A23: FDS-02-008 | B23: Terminal as Cell Kind | C23: 2.5 Terminals | D23: Terminal & Login | E23: MVP | G23: FAT-TERM-010, FAT-TERM-020, FAT-TERM-030, FAT-TERM-040 | H23: Covered (4)
A24: FDS-02-009 | B24: Cell Context Selection | C24: 2.5 Terminals | D24: Terminal & Login | E24: MVP | G24: FAT-TERM-060, FAT-TERM-070, FAT-TERM-080 | H24: Covered (3)
A25: FDS-02-010 | B25: Terminal Behavior Determined by Assigned View | C25: 2.5 Terminals | D25: Terminal & Login | E25: MVP | G25: FAT-TERM-090, FAT-TERM-100 | H25: Covered (2)
A26: FDS-02-011 | B26: Cell Context Change Rules | C26: 2.5 Terminals | D26: Terminal & Login | E26: MVP | G26: FAT-TERM-110, FAT-TERM-120 | H26: Covered (2)
A27: FDS-02-012 | B27: Part ↔ Cell Eligibility | C27: 2.5 Terminals | D27: Terminal & Login | E27: MVP | G27: FAT-TERM-130, FAT-TERM-140, FAT-TERM-150 | H27: Covered (3)
A28: FDS-02-013 | B28: Mobile-Friendly Design Input | C28: 2.5 Terminals | D28: Terminal & Login | E28: MVP | G28: FAT-TERM-160 | H28: Covered (1)
A29: FDS-02-014 | B29: Honda RFID Forward-Compatibility | C29: 2.5 Terminals | D29: Terminal & Login | E29: FUTURE | H29: Out-of-scope
A30: FDS-03-001 | B30: Item Records | C30: 3.1 Item Master | D30: Item Master | E30: MVP | G30: FAT-ITM-010, FAT-ITM-020, FAT-ITM-030, FAT-ITM-040, FAT-ITM-050 | H30: Covered (5)
A31: FDS-03-002 | B31: Item Types | C31: 3.1 Item Master | D31: Item Master | E31: MVP | G31: FAT-ITM-060 | H31: Covered (1)
A32: FDS-03-003 | B32: Item Deprecation | C32: 3.1 Item Master | D32: Item Master | E32: MVP | G32: FAT-ITM-070 | H32: Covered (1)
A33: FDS-03-004 | B33: BOM Structure | C33: 3.2 Bills of Material | D33: Routes & BOMs | E33: MVP | F33: 3.4.2 | G33: FAT-RB-010, FAT-RB-020 | H33: Covered (2)
A34: FDS-03-005 | B34: BOM Versioning | C34: 3.2 Bills of Material | D34: Routes & BOMs | E34: MVP | G34: FAT-RB-030, FAT-RB-040 | H34: Covered (2)
A35: FDS-03-006 | B35: Single-Level BOMs | C35: 3.2 Bills of Material | D35: Routes & BOMs | E35: MVP | G35: FAT-RB-050 | H35: Covered (1)
A36: FDS-03-007 | B36: Route Structure | C36: 3.3 Route Templates | D36: Routes & BOMs | E36: MVP | F36: 3.11.1–3.11.4 | G36: FAT-RB-060 | H36: Covered (1)
A37: FDS-03-008 | B37: Route Steps | C37: 3.3 Route Templates | D37: Routes & BOMs | E37: MVP | G37: FAT-RB-070, FAT-RB-080 | H37: Covered (2)
A38: FDS-03-009 | B38: Route Steps Do Not Prescribe Machines | C38: 3.3 Route Templates | D38: Routes & BOMs | E38: MVP | G38: FAT-RB-090 | H38: Covered (1)
A39: FDS-03-010 | B39: Route Versioning | C39: 3.3 Route Templates | D39: Routes & BOMs | E39: MVP | G39: FAT-RB-100 | H39: Covered (1)
A40: FDS-03-011 | B40: Operation Sequence Flexibility | C40: 3.3 Route Templates | D40: Routes & BOMs | E40: MVP | F40: 3.11.10 | G40: FAT-RB-110 | H40: Covered (1)
...

Sheet Environment & Platform
A1: TestID | B1: Workflow | C1: Precondition | D1: Step | E1: Expected Result | F1: Result | G1: Witness | H1: Date | I1: Notes
A2: FDS-01-001 — Ignition Gateway
A3: FAT-ENV-010 | B3: Gateway inspection | C3: FAT gateway running | D3: On the Ignition Gateway status page, show the Gateway version, OS, and running module set | E3: Single Ignition Gateway on Windows Server (>= 2019) hosting the Perspective project, OPC connections, Tag Historian, and Gateway scripts; version and edition displayed | I3: witnessed by inspection
A4: FAT-ENV-020 | B4: Gateway inspection | C4: Gateway status page open | D4: Show the loaded MPP Perspective project and its Gateway timer/scheduled scripts | E4: MPP project is loaded and running; Gateway-scoped scripts (shift ticker, PLC watchers) are present and enabled
A5: FDS-01-002 — Database Server
A6: FAT-ENV-030 | B6: Database server inspection | C6: SQL Server instance reachable | D6: Connect to the MES database and show product version, edition, and the schema list | E6: SQL Server 2022 Standard; MES database exposes the 8 schemas (Location, Parts, Lots, Workorder, Quality, OEE, Tools, Audit) | I6: witnessed by inspection
A7: FDS-01-003 — Redundancy
A8: FAT-ENV-040 | B8: Redundancy posture | C8: Gateway config visible | D8: Confirm the current redundancy configuration | E8: No gateway redundancy is configured (out of current scope); architecture confirmed to permit adding a redundant gateway later with no schema or application change | I8: SHOULD-level future-readiness, not a running feature
A9: FDS-01-004 — Development/Test Environment
A10: FAT-ENV-050 | B10: Dev/Test environment | C10: Access to non-prod environment | D10: Show the separate development/test Ignition Gateway and its database | E10: A dedicated dev/test gateway exists mirroring production spec, backed by its own MES database (MPP_MES_Dev / MPP_MES_Test), separate from production | I10: witnessed by inspection
A11: FDS-01-005 — Event Immutability (FRS 3.5.4, 3.9.6)
A12: FAT-ENV-060 | B12: Event immutability | C12: A LOT with recorded production events | D12: Attempt to alter or delete a posted production/genealogy event; then record a correction | E12: Evidence and traceability records cannot be updated or deleted; the correction is written as a NEW event, leaving the original intact (append-only)
A13: FDS-01-006 — External Interface Dispatch Pattern (FRS 3.17.4, 5.5.1)
A14: FAT-ENV-070 | B14: Interface logging | C14: Terminal with an assigned Zebra printer | D14: Trigger an external call (print a shipping/LOT label) and open Audit.InterfaceLog | E14: The external call is logged to Audit.InterfaceLog with request payload, response/result, and any error condition
A15: FDS-01-007 — Tag Historian Separation (FRS 3.4.10, 5.5.1)
A16: FAT-ENV-080 | B16: Tag Historian separation | C16: Gateway Tag Historian configured | D16: Show where process/tag values are historized versus where MES transactional records live | E16: Time-series process data goes to the Ignition Tag Historian in a SEPARATE database (e.g. MPP_MES_Historian); MES transactional tables hold no tag time-series | I16: may share the instance, never the database
A17: FDS-01-013 — BOM Source System at Cutover
A18: FAT-ENV-090 | B18: BOM cutover import | C18: A sample Flexware BOM export (JSON) prepared | D18: Run Parts.Bom_BulkLoadFromSeed against the sample export | E18: Parts.Bom / Parts.BomLine are populated in one transaction; imported BOMs enter as VersionNumber 1 in Published state; re-running is idempotent | I18: proves the cutover BOM seed path
A19: FAT-ENV-100 | B19: BOM cutover import | C19: Bulk-load import loaded | D19: Submit an export whose child item does not resolve to a Parts.Item | E19: The entire import aborts with an error listing the unresolved child item(s); no partial BOM rows are written
A20: FDS-01-008 — OPC Server Connections
A21: FAT-ENV-110 | B21: OPC connections | C21: FAT uses simulated devices | D21: Show the Gateway OPC/device connections (or the MPP_Sim simulator standing in for them) | E21: OPC/device connections are configured for the scale, assembly PLC, vision, and MIP roles; during FAT these are exercised via the MPP_Sim simulator (live OPC verified at SAT) | I21: live OmniServer/TOPServer/Cognex/MIP deferred to SAT (FDS-15-004)
A22: FDS-01-009 — OPC Tag Namespace
A23: FAT-ENV-120 | B23: OPC tag namespace | C23: OPC/simulated tags visible | D23: Inspect the tag paths for the configured devices | E23: Tags follow the consistent [Server]/[Line].[Device].[Tag] namespace convention per the OPC tag map | I23: witnessed by inspection
A24: FDS-01-010 — Authentication (FRS 5.3)
A25: FAT-ENV-130 | B25: Authentication | C25: AD user source configured | D25: Log in to an interactive (Quality/Supervisor/Engineering/Admin) screen with an AD credential | E25: Interactive user authenticates against Active Directory via the Ignition AD User Source
A26: FAT-ENV-140 | B26: Authentication | C26: Shop-floor terminal open | D26: Identify an operator at a shop-floor terminal | E26: Operator is identified by initials entry only (no AD authentication); the AppUser row exists for attribution and carries no AD account
A27: FDS-01-011 — Authorization
A28: FAT-ENV-150 | B28: Authorization | C28: Two users in different AD groups | D28: Access a role-restricted screen/function as an authorized then an unauthorized user | E28: Access is granted or denied per Ignition security roles/zones mapped from AD groups; no custom RBAC tables involved
A29: FDS-01-012 — Audit Attribution
A30: FAT-ENV-160 | B30: Audit attribution | C30: Operator logged in at a known terminal | D30: Perform a state-changing action and open the resulting audit/event record | E30: The record carries the acting AppUser.Id and the TerminalLocationId; system-triggered events are attributed to the designated system user
A31: FDS-01-014 — External Integration Pattern (Gateway-script-async)
A32: FAT-ENV-170 | B32: Async dispatch | C32: Container ready to complete with an assigned printer | D32: Complete a container and observe the label dispatch | E32: The proc commits DB state (ShippingLabel row, PrintedAt NULL) and returns immediately; the print is dispatched async via sendRequestAsync — the operator is not blocked on printer latency
A33: FAT-ENV-180 | B33: Async dispatch | C33: Print handler forced to fail (printer offline) | D33: Complete a container while the printer is unavailable | E33: Failure surfaces to the operator from persisted DB state (not in-flight handler state) and is logged; visibility survives a Gateway restart
A34: FDS-13-004 — Macola Scope Boundary [FUTURE]
A35: (out of scope — no test required)
A36: FDS-13-005 — Intelex Scope Boundary [FUTURE]
A37: (out of scope — no test required)
A38: FDS-13-006 — SCADA Scope Boundary [FUTURE]
A39: (out of scope — no test required)
A40: FDS-14-001 — Seed Data (MVP — Not Conditional)
...

Sheet Plant Hierarchy
A1: TestID | B1: Workflow | C1: Precondition | D1: Step | E1: Expected Result | F1: Result | G1: Witness | H1: Date | I1: Notes
A2: FDS-02-001 — ISA-95 Location Types
A3: FAT-PH-010 | B3: ISA-95 location types seeded | C3: Config Tool open at Plant Hierarchy | D3: Inspect the location-type tiers available in the hierarchy | E3: Five ISA-95 types exist — Enterprise, Site, Area, Work Center, Cell — with ascending hierarchy levels
A4: FAT-PH-020 | B4: Location types are read-only | C4: Config Tool open at Plant Hierarchy | D4: Attempt to rename or delete one of the five location types | E4: No edit/delete affordance for the LocationType tiers; they are seed-locked and not editable by engineering
A5: FDS-02-002 — Hierarchy Enforcement
A6: FAT-PH-030 | B6: Flexible tier nesting | C6: An Area with no Work Center tier beneath it | D6: Create a Cell directly under the Area | E6: Cell is accepted as a direct child of the Area — strict sequential tiers are not required, only child level >= parent level
A7: FAT-PH-040 | B7: Relocation via deprecate + recreate | C7: An existing Location in the tree | D7: Attempt to change a Location's parent | E7: No reparent control exists; ParentLocationId is immutable — relocation is done by deprecating the row and creating a new one under the new parent, preserving history
A8: FDS-02-003 — Areas as Instances (FRS 3.3.2, 3.7.1)
A9: FAT-PH-050 | B9: Areas seeded as instances | C9: Config Tool open at Plant Hierarchy | D9: Inspect the Area-tier nodes under the Site | E9: MPP's operational areas exist as Location instances (Die Cast, Trim Shop, Machine Shop, Production Control, Quality Control) with ProductionArea / SupportArea definitions
A10: FDS-02-004 — Location Type Definitions (Kinds)
A11: FAT-PH-060 | B11: Location kinds per tier | C11: Config Tool open at the Location Type Definition editor | D11: Review the definitions (kinds) available within each tier | E11: Each tier lists its seeded kinds (e.g. Cell -> Terminal, DieCastMachine, CNCMachine, TrimPress, InventoryLocation, Scale); every Location instance references exactly one
A12: FAT-PH-070 | B12: Add a new kind | C12: Location Type Definition editor open | D12: Create a new LocationTypeDefinition under a tier and save | E12: New kind is added and available for new Location instances with no schema change; change is audited
A13: FDS-02-005 — Attribute Schemas per Definition
A14: FAT-PH-080 | B14: Attribute schema per kind | C14: A Location Type Definition selected in the editor | D14: Define attribute definitions on the kind and compare against another kind at the same tier | E14: Attributes attach per-definition (e.g. DieCastMachine carries Tonnage/RefCycleTime; Terminal carries IpAddress/DefaultPrinter/HasBarcodeScanner) — schemas are disjoint across kinds
A15: FDS-02-006 — Attribute Value Integrity
A16: FAT-PH-090 | B16: Attribute value integrity | C16: A Terminal-kind Location selected in the tree | D16: Open its attribute values and review the offered attributes | E16: Only attributes belonging to the Terminal definition are offered; a DieCastMachine attribute (e.g. Tonnage) cannot be set on a Terminal
A17: FDS-02-007 — Machine Seed Data
A18: FAT-PH-100 | B18: Machine seed data loaded | C18: Deployment seed applied | D18: Verify the FRS Appendix B machines are present as Cell Locations | E18: The ~230 machines are loaded as Cell-tier Locations under their Areas/Work Centers with appropriate kinds and seeded attribute values (tonnage, cycle time where available) | I18: deploy-day / cutover seed
A19: FDS-03-014 — Eligibility Map with Hierarchy Cascade (FRS 3.4.7)
A20: FAT-PH-110 | B20: Eligibility hierarchy cascade | C20: A part with an ItemLocation row at the Die Cast Area tier, no Cell-level row | D20: Resolve eligibility for that part at a descendant Cell | E20: Eligibility resolves by walking up Cell -> Work Center -> Area -> Site; the Area-tier row matches and the part is eligible at the Cell
A21: FAT-PH-120 | B21: No eligibility match rejects | C21: A part with no ItemLocation row anywhere in a Cell's chain | D21: Resolve eligibility for that part at the Cell | E21: Eligibility check returns not-eligible with a clear reject message naming the part and cell
A22: FDS-03-015 — Eligibility Management
A23: FAT-PH-130 | B23: Eligibility management CRUD | C23: Configuration Tool Eligibility screen open for an item | D23: Add an ItemLocation row (target any tier — Area, Work Center, or Cell), update it, and remove another | E23: Rows are created/updated/removed with the Location picker allowing any tier; every change is logged to the config audit log
A24: FDS-03-018 — Consumption Metadata on Item-Location Eligibility
A25: FAT-PH-140 | B25: Consumption metadata on eligibility | C25: An eligibility row being edited | D25: Enable IsConsumptionPoint and set Min / Max / Default quantities | E25: Min/Max/Default inputs appear when IsConsumptionPoint is enabled and persist on the row; they drive the runtime Allocations grid (pre-fill Default, validate Min <= entered <= Max) | I25: metadata drives shop-floor scan-in

Sheet Item Master
A1: TestID | B1: Workflow | C1: Precondition | D1: Step | E1: Expected Result | F1: Result | G1: Witness | H1: Date | I1: Notes
A2: FDS-03-001 — Item Records
A3: FAT-ITM-010 | B3: Item master CRUD | C3: Config Tool open at Item Master | D3: Create a new part and edit an existing part | E3: Part is created and saved; edits persist; changes are audited (config log)
A4: FAT-ITM-020 | B4: Item master fields | C4: An item open in Item Master | D4: Review the item's data fields | E4: Part number, description, units of measure, and related master-data fields are present and editable
A5: FAT-ITM-030 | B5: Sub-lot quantity attribute | C5: An item open in Item Master | D5: Set the default sub-lot quantity | E5: Default Sub-Lot Quantity is stored on the part
A6: FAT-ITM-040 | B6: Macola part number | C6: An item open in Item Master | D6: Enter the associated Macola part number | E6: Macola part number attribute is stored and displayed
A7: FAT-ITM-050 | B7: Max LOT size reasonability | C7: A part with Max LOT Size set | D7: On the shop floor, attempt to set a piece count above Max LOT Size | E7: Entry is flagged/blocked as unreasonable per the part's Max LOT Size | I7: enforcement is shop-floor
A8: FDS-03-002 — Item Types
A9: FAT-ITM-060 | B9: Item types | C9: Config Tool open at Item Master | D9: Assign an item type to a part | E9: Item type is stored and constrains downstream routing/area eligibility
A10: FDS-03-003 — Item Deprecation
A11: FAT-ITM-070 | B11: Item deprecation | C11: An item with no live LOTs | D11: Deprecate a part | E11: Part is soft-deleted (DeprecatedAt); owned config cascades; blocked if a live LOT exists
A12: Blue Ridge / Non-FDS
A13: FAT-ITM-080 | B13: PLC part mapping | C13: An item that maps to a PLC part identifier | D13: Set the item's PlcId in Item Master | E13: PlcId is saved on the item and used by vision/PLC part verification

Sheet Routes & BOMs
A1: TestID | B1: Workflow | C1: Precondition | D1: Step | E1: Expected Result | F1: Result | G1: Witness | H1: Date | I1: Notes
A2: FDS-03-004 — BOM Structure (FRS 3.4.2)
A3: FAT-RB-010 | B3: Create a BOM | C3: Config Tool open at Item Master BOMs section for an assembled item | D3: Create a BOM and add component lines | E3: BOM is created with parent item, version number, and effective date; each line specifies child item, quantity per parent, UOM, and sort order
A4: FAT-RB-020 | B4: Reorder BOM lines | C4: A draft BOM with multiple lines | D4: Reorder lines using the up/down arrow buttons | E4: Line sort order changes via arrows (no drag-and-drop); order persists on save
A5: FDS-03-005 — BOM Versioning
A6: FAT-RB-030 | B6: BOM versioning | C6: A published BOM | D6: Revise the BOM (create new version) and publish it | E6: A new version is created with a new EffectiveFrom; the prior version is soft-deleted (DeprecatedAt set) but remains queryable for historical traceability
A7: FAT-RB-040 | B7: Historical BOM accuracy | C7: A part with a superseded BOM version | D7: Inspect an old production/LOT record that used the superseded version | E7: Production records FK to the BOM version active at time of manufacture; the historical version is preserved and resolvable | I7: traceability check
A8: FDS-03-006 — Single-Level BOMs
A9: FAT-RB-050 | B9: Single-level BOM | C9: A BOM open in the editor | D9: Review the BOM structure | E9: BOM is single-level (one parent -> child lines); no nested/multi-level explosion is authored in the editor
A10: FDS-03-007 — Route Structure (FRS 3.11.1–3.11.4)
A11: FAT-RB-060 | B11: Create a route template | C11: Config Tool open at Item Master Routes section for a manufactured item | D11: Create a route template | E11: Route is created with item, version number, name, and effective date; soft-delete supported
A12: FDS-03-008 — Route Steps
A13: FAT-RB-070 | B13: Add route steps | C13: A draft route template | D13: Add ordered route steps | E13: Each step references an operation template, carries a sequence number and a required flag
A14: FAT-RB-080 | B14: Reorder route steps | C14: A draft route with multiple steps | D14: Reorder steps using the up/down arrow buttons | E14: Step sequence changes via arrows and renumbers; order persists on save
A15: FDS-03-009 — Route Steps Do Not Prescribe Machines
A16: FAT-RB-090 | B16: Steps do not prescribe machines | C16: A route step open in the editor | D16: Inspect what a route step references | E16: Step references an operation template (operation role) only; there is no machine or location field — the operator picks an eligible machine at runtime
A17: FDS-03-010 — Route Versioning
A18: FAT-RB-100 | B18: Route versioning | C18: A published route template | D18: Revise the route (create new version) and publish it | E18: A new version is created; the prior version is retained and production records FK to the version active at execution time
A19: FDS-03-011 — Operation Sequence Flexibility (FRS 3.11.10)
A20: FAT-RB-110 | B20: Operation sequence flexibility | C20: A route in use | D20: Insert an additional operation and delete an operation within the route | E20: Operations can be inserted and removed within the route, supporting parts that skip steps or need extra operations
A21: FDS-14-005 — Flexware BOM Import
A22: FAT-RB-120 | B22: Flexware BOM import at cutover | C22: Flexware BOM export delivered by MPP IT; every Parent/Child part resolves to an active Item | D22: Run the one-shot BOM bulk-load at cutover | E22: Pre-flight reports any unresolved part references and blocks until fixed; BOMs seed into Parts.Bom/BomLine as Published; re-run is idempotent (unchanged skip, changed create a new version) | I22: cutover/deploy-day step; bulk-load proc + export format owed by MPP IT

Sheet Op Templates & Quality Specs
A1: TestID | B1: Workflow | C1: Precondition | D1: Step | E1: Expected Result | F1: Result | G1: Witness | H1: Date | I1: Notes
A2: FDS-03-012 — Operation Template Design
A3: FAT-OQ-010 | B3: Create an operation template | C3: Config Tool open at the Operation Templates editor | D3: Create a new operation template | E3: Template is created with Code, Name, an OperationType role (DieCast, TrimIn/Out, MachiningIn/Out, AssemblyIn/Out), and optional description; starts in Draft
A4: FAT-OQ-020 | B4: Data collection fields | C4: An operation template being edited | D4: Attach data collection fields and mark some required | E4: Fields are attached via the OperationTemplateField junction (from the DataCollectionField vocabulary) each with an IsRequired flag; the template is reusable across products
A5: FAT-OQ-030 | B5: Operation template versioning | C5: A published operation template | D5: Create a new version of the template | E5: New version is created following the Draft/Published/Deprecated lifecycle; the prior version is retained
A6: FDS-03-013 — Operation Templates Drive Screen Behavior (FRS 3.11.6)
A7: FAT-OQ-040 | B7: Templates drive screen behavior | C7: Two templates with different field sets (e.g. a Die Cast role vs an Assembly role) | D7: Open the production screen for a LOT resolving to each template | E7: The production screen renders inputs from the template's OperationTemplateField rows — die/cavity/weight for the die-cast role, serial/material-verification for assembly; required fields enforced | I7: rendering is shop-floor; config drives it
A8: FDS-08-008 — Quality Spec Management (FRS 3.16.1)
A9: FAT-OQ-050 | B9: Create a quality spec | C9: Config Tool open at the Quality Specs editor | D9: Create a quality spec | E9: Spec is created with a name, an optional associated item, an optional associated operation template, and a list of measurable attributes
A10: FAT-OQ-060 | B10: Manage quality specs | C10: Existing quality specs listed | D10: Edit a spec's metadata (name, associations) and save | E10: Changes persist and are audited; specs are engineering-managed via the configuration tool
A11: FDS-08-009 — Quality Spec Versioning (FRS 3.16.2)
A12: FAT-OQ-070 | B12: Quality spec versioning | C12: A published quality spec version | D12: Revise the spec (create new version) and publish | E12: A new version is created with a new effective date; the prior version is soft-deleted; inspection records FK to the version active at time of inspection
A13: FDS-08-010 — Quality Spec Attributes
A14: FAT-OQ-080 | B14: Quality spec attributes | C14: A quality spec version being edited | D14: Define measurable attributes and reorder them | E14: Each attribute carries name / data type / UOM / target value / lower limit / upper limit / required flag / sort order; reordering is via up/down arrows
A15: FAT-OQ-090 | B15: Attributes drive inspection screen | C15: A published spec with defined attributes | D15: Open the inspection screen for a LOT governed by the spec | E15: The inspection screen renders input fields dynamically from the spec's attribute definitions | I15: rendering is shop-floor; config drives it

Sheet Container Configs
A1: TestID | B1: Workflow | C1: Precondition | D1: Step | E1: Expected Result | F1: Result | G1: Witness | H1: Date | I1: Notes
A2: FDS-03-016 — Container Config (FRS 3.9.7)
A3: FAT-CC-010 | B3: Create a container config | C3: Config Tool open at Item Master Container Config section for a finished good | D3: Create a container configuration | E3: Config is saved with trays per container, parts per tray, serialized flag, dunnage code, and customer code
A4: FAT-CC-020 | B4: Container config persists | C4: A finished good with a saved container config | D4: Reopen the item and review the container config | E4: Fields persist and are the values that drive automatic container lifecycle management on the shop floor
A5: FDS-03-017 — Container Closure Logic
A6: FAT-CC-030 | B6: Closure method + capacity | C6: A non-serialized finished good's container config | D6: Set the ClosureMethod and review the derived capacity | E6: ClosureMethod is selectable (ByCount / ByWeight / ByVision); container capacity resolves to TraysPerContainer x PartsPerTray (capped by Item.MaxParts if set) | I6: auto-close fires on shop floor
A7: FAT-CC-040 | B7: Serialized vs non-serialized | C7: Two configs — one serialized line, one non-serialized | D7: Compare how each is configured for closure | E7: Serialized config closes by part count via the MIP handshake; non-serialized config is two-stage (tray validates per ClosureMethod, container count increments per tray pass) | I7: enforcement is shop-floor
A8: FDS-03-019 — Per-Item Per-Location Piece Cap
A9: FAT-CC-050 | B9: Per-item per-location piece cap | C9: An item with Parts.Item.MaxParts set | D9: On the shop floor, attempt to scan pieces into a location that would exceed MaxParts for that item | E9: Scan-in is rejected when total pieces of the item across all non-Closed LOTs at the location plus the incoming count would exceed MaxParts | I9: enforcement is shop-floor
A10: FDS-03-020 — Lineside Inventory Cap
A11: FAT-CC-060 | B11: Lineside inventory cap | C11: A Cell with a LinesideLimit LocationAttribute set | D11: On the shop floor, attempt a scan-in that would exceed the Cell's total-piece limit | E11: Scan-in is rejected when current lineside pieces across all items plus the incoming quantity would exceed LinesideLimit | I11: LinesideLimit set via Plant Hierarchy attribute; enforcement is shop-floor
A12: FDS-03-021 — Tray-Divisibility Validation on Work Order
A13: FAT-CC-070 | B13: Tray-divisibility on work order | C13: A finished good with a container config (PartsPerTray set) | D13: Create/edit a work order with a target quantity not evenly divisible by the tray quantity | E13: Non-divisible target is rejected with a specific error; at WO Close a non-divisible good count is blocked unless a supervisor overrides via AD elevation (reason logged) | I13: Work Orders CONDITIONAL; validates against ContainerConfig

Sheet Code Tables
A1: TestID | B1: Workflow | C1: Precondition | D1: Step | E1: Expected Result | F1: Result | G1: Witness | H1: Date | I1: Notes
A2: FDS-08-016 — Defect Code Management
A3: FAT-CT-010 | B3: Defect code CRUD | C3: Config Tool open at Quality > Defect Codes | D3: Create a new defect code and edit an existing one | E3: Code is created and saved; edits persist; changes are audited (config log)
A4: FAT-CT-020 | B4: Defect code fields | C4: A defect code open in the editor | D4: Set the code's Area and IsExcused flag | E4: Defect code carries Code, Description, Area association, and IsExcused; IsExcused feeds future OEE quality math
A5: FAT-CT-030 | B5: Defect code seed load | C5: Freshly deployed database | D5: Verify the FRS Appendix E defect codes were seeded | E5: Defect codes loaded from Appendix E (153 rows), each associated with an area (Die Cast, Machine Shop, Trim Shop, Production Control, Quality Control, HSP) with IsExcused set per the appendix | I5: deploy-day check
A6: FAT-CT-040 | B6: Defect code deprecation | C6: An active defect code | D6: Deprecate a defect code | E6: Code is soft-deleted (DeprecatedAt) and drops out of active lists; historical references are retained
A7: FDS-08-017 — Area Filtering
A8: FAT-CT-050 | B8: Area filtering — Die Cast | C8: A Die Cast production screen | D8: Open the defect/scrap reason picker | E8: Only Die Cast area defect codes are offered
A9: FAT-CT-060 | B9: Area filtering — cross-check | C9: A Machine Shop production screen | D9: Open the defect picker on a Machine Shop screen | E9: Only Machine Shop codes are shown; Die Cast-only codes are absent
A10: FDS-09-006 — Reason Code Seed Data
A11: FAT-CT-070 | B11: Reason code seed load | C11: Freshly deployed database | D11: Verify the downtime reason codes were seeded | E11: 353 downtime reason codes loaded from FRS Appendix D; each carries code, description, area, reason type, and IsExcused | I11: deploy-day check
A12: FAT-CT-080 | B12: Reason code fields | C12: A downtime reason code in the list | D12: Inspect a reason code's fields | E12: Code, description, area, reason type, and IsExcused are all present
A13: FDS-09-007 — Reason Types
A14: FAT-CT-090 | B14: Reason types seeded | C14: Freshly deployed database | D14: Review the seeded downtime reason types | E14: Six reason types present: Equipment, Miscellaneous, Mold, Quality, Setup, Unscheduled
A15: FAT-CT-100 | B15: Reason type selection | C15: Downtime entry screen at a machine | D15: Open the reason-type selector then pick a code | E15: Operator selects the reason type first (from the six seeded types), then the specific code within that type

Sheet Shift Schedules
A1: TestID | B1: Workflow | C1: Precondition | D1: Step | E1: Expected Result | F1: Result | G1: Witness | H1: Date | I1: Notes
A2: FDS-09-008 — Shift Schedules
A3: FAT-SS-010 | B3: Shift schedule config | C3: Config Tool open at Shift Schedules (/shifts) | D3: Create a new shift schedule (name, start, end, days-of-week, effective date) | E3: Schedule saved with Name, StartTime, EndTime, DaysOfWeekBitmask (Mon=1..Sun=64), and EffectiveFrom; creation is audit-logged
A4: FAT-SS-020 | B4: Common shift patterns | C4: Shift Schedules screen | D4: Configure First Shift (6:00am–2:00pm M–F) and Second Shift (2:00pm–10:00pm M–F) | E4: Both schedules persist with correct times and a Mon–Fri days bitmask
A5: FAT-SS-030 | B5: Overnight shift | C5: Shift Schedules screen | D5: Create a schedule whose end time is earlier than its start time | E5: Overnight shift (EndTime < StartTime) is accepted as valid
A6: FAT-SS-040 | B6: Unique schedule name | C6: An existing shift schedule | D6: Attempt to create another schedule with the same name | E6: System rejects the duplicate with a clear message
A7: FAT-SS-050 | B7: Shift schedule soft-delete | C7: An active shift schedule | D7: Deprecate the schedule | E7: Schedule is soft-deleted (DeprecatedAt), not overwritten; EffectiveFrom preserves the schedule across time
A8: FAT-SS-060 | B8: Edit shift schedule | C8: An existing shift schedule | D8: Change its start/end time and save | E8: Edit persists and is audit-logged
A9: FDS-09-012 — Shift Schedule Import
A10: FAT-SS-070 | B10: Shift schedule import idempotency | C10: Shift schedules already loaded | D10: Re-apply the schedule set with a revised sheet (updated + new rows) | E10: Existing rows update and new rows add without duplicating (idempotent by unique name) | I10: bulk spreadsheet import is a cutover step
A11: FAT-SS-080 | B11: Post-import edit audit | C11: A shift schedule maintained in the Config Tool | D11: Make a manual edit after import | E11: Manual Configuration Tool edit is audit-logged

Sheet PLC Device Mapping
A1: TestID | B1: Workflow | C1: Precondition | D1: Step | E1: Expected Result | F1: Result | G1: Witness | H1: Date | I1: Notes
A2: FDS-10-001 — MIP Touch Points
A3: FAT-PLC-010 | B3: Serialized MIP touch points | C3: MPP_Sim running; a SerializedMipStation UDT instance exists with a /plc-devices mapping to its terminal | D3: Inspect the serialized MIP UDT instance members against the 5GO_AP4 Touchpoint Agreement | E3: Instance exposes DataReady, TransInProc, PartSN, PartValid, HardwareInterlockEnforced, WatchDog, ContainerCount, PartType and the alarm member per FDS-10-001 | I3: Simulator-validated against MPP_Sim; live device tag-map (OpcServer/Device/BasePath) applied at hardware commissioning
A4: FAT-PLC-020 | B4: Serialized MIP touch points | C4: A TerminalPlcDevice mapping row exists for the station | D4: Open /plc-devices and confirm the serialized station terminal is bound to its `[MPP]PlcDevices/<device>` instance path | E4: Mapping resolves (PlcWatcher.dispatch finds the terminal + device type); edges on the instance route to the SerializedMip watcher
A5: FDS-10-002 — MIP Transaction Flow
A6: FAT-PLC-030 | B6: Serialized MIP transaction flow | C6: A LOT is queued at the assembly-out terminal; Sim Panel /dev/sim/plc open on the device | D6: Seed a valid PartSN (>=6) with HardwareInterlockEnforced=True and fire DataReady | E6: MES sets TransInProc, reads PartSN + interlock, mints the serialized part against the FIFO front LOT, writes PartValid=1, then resets TransInProc + DataReady; a PlcHandshake InterfaceLog row is written | I6: Simulator-validated via /dev/sim/plc against the live watcher
A7: FAT-PLC-040 | B7: Serialized MIP transaction flow | C7: Serialized MIP device selected in the Sim Panel; a LOT queued at the terminal | D7: Fire DataReady with HardwareInterlockEnforced=False and a blank PartSN | E7: Validation is skipped (NoRead path, FDS-06-012); SerializedPart_Mint auto-generates a serial and the part is accepted with PartValid=1 | I7: Simulator-validated
A8: FDS-10-003 — MES Alarms
A9: FAT-PLC-050 | B9: MIP alarms | C9: A serialized part with a given PartSN already exists | D9: Fire DataReady re-using that duplicate PartSN | E9: Mint is rejected — PartValid=0, alarm text written (HMI-gated), and a failed PlcHandshake row is logged to Audit.InterfaceLog | I9: Duplicate dedup is enforced in SerializedPart_Mint; simulator-validated
A10: FAT-PLC-060 | B10: MIP alarms | C10: Serialized MIP device in the Sim Panel | D10: Attempt the Invalid-PartSN and Low-Inventory alarm cases | E10: Alarm message surfaces to the operator/HMI for each | I10: Only the duplicate/rejection alarm is wired today; the invalid-PartSN min-length gate and the low-inventory-threshold alarm are proc-level commissioning fill-ins (flagged in the runbook §E)
A11: FDS-10-004 — Disposition-Based Lines
A12: FAT-PLC-070 | B12: Non-serialized disposition line | C12: A NonSerializedMipStation instance mapped to a 5A2-style terminal; Sim Panel open | D12: Fire DataReady on the non-serialized device | E12: Watcher sets TransInProc, acknowledges the handshake, logs it, and resets TransInProc + DataReady | I12: Handshake choreography simulator-validated; the FG + tray-piece-count line config (_resolveLineConfig) is a commissioning fill-in — until supplied the completion mint is deliberately skipped (not faked), per runbook §E
A13: FAT-PLC-080 | B13: Non-serialized disposition line | C13: A TrayInspectionStation device selected in the Sim Panel | D13: Fire InspectionComplete with a mix of PartDisposition slot flags set | E13: The 18 PartDisposition slots are read by the watcher | I13: Disposition slots are read; the passed-parts-count / open-container tray-close bookkeeping is line-specific commissioning (runbook §E)
A14: FDS-10-005 — Vision / Operator Conflict — Line-Stop Semantics
A15: FAT-PLC-090 | B15: Vision line-stop | C15: A LOT queued at the tray-inspection terminal whose Item.PlcId is set; Sim Panel open | D15: Fire TrayLocked on the tray-inspection device | E15: The front FIFO LOT's Item.PlcId is written to the instance PartNumber member (the PLC vision recipe is selected before inspection) | I15: Simulator-validated
A16: FAT-PLC-100 | B16: Vision line-stop | C16: TrayLocked already fired (recipe selected) for the front LOT | D16: Fire InspectionComplete with a VisionPartNumber that does NOT match the expected recipe | E16: LINE STOP — OkToContinue stays false (tray left locked, no release), a PlcLineStop event is written to Audit.InterfaceLog, and the HMI alarm is raised (gated); the LOT's LotStatusCode is left untouched (no Hold) | I16: Simulator-validated; line-stop signal to the PLC is asserted by holding OkToContinue false. Optional formal Quality.Hold on mismatch is a deliberate policy hook, not auto-placed
A17: FAT-PLC-110 | B17: Vision line-stop | C17: TrayLocked already fired for the front LOT | D17: Fire InspectionComplete with a VisionPartNumber matching the expected recipe | E17: OkToContinue=1 (tray released) and the ByVision tray close runs through Assembly_CompleteTray (mints the FG LOT + consumes BOM) | I17: Simulator-validated
A18: FDS-10-009 — 10-Consecutive-Fail Escalation
A19: FAT-PLC-120 | B19: Consecutive-fail escalation | C19: A tray-inspection cell | D19: Drive 10 consecutive vision-mismatch failures at the cell and confirm the escalation behaviour | E19: On the 10th consecutive fail the line leader is auto-escalated (LeaderEscalationFlagged), a supervisor-dashboard badge fires, supervisor AD elevation (FDS-04-007) is required to resume, and the counter resets on the next pass | I19: NOT YET WIRED — the consecutive-fail counter, LeaderEscalationFlagged event, supervisor-resume gate, and the LineStopConsecutiveFailThreshold LocationAttribute are a commissioning fill-in. Today each mismatch records an independent line-stop with no cross-cycle counter
A20: FDS-10-010 — Failure-Type Branching
A21: FAT-PLC-130 | B21: Failure-type branching | C21: A tray-inspection cell | D21: Exercise each failure type and confirm the branch | E21: Wrong-part (vision != operator) flags the leader immediately; wrong-orientation stops but does not escalate; PartDisposition fail counts toward the 10-fail threshold; barcode mis-scan does not stop the line | I21: NOT YET WIRED — failure-type branching is not implemented; the watcher records a uniform vision-mismatch line-stop. Commissioning fill-in
A22: FDS-10-011 — Hold Release Path (FRS 3.16.10)
A23: FAT-PLC-140 | B23: Hold release path | C23: A LOT is on Hold | D23: As a Quality-role user, AD-elevate (FDS-04-007) and release the hold via the Quality hold screen | E23: The HoldEvent row closes (ReleasedAt set) and the LOT's LotStatusCode returns to Good (Hold_Release) | I23: Witnessable directly in the Quality hold UI
A24: FAT-PLC-150 | B24: Hold release path | C24: A LOT is on Hold; logged in as an operator without elevation | D24: Attempt to release the hold directly | E24: Release is blocked — operators cannot release holds; the action is elevation-gated
A25: FDS-10-012 — Controlled Run Tag (CRT) Workflow
A26: FAT-PLC-160 | B26: CRT workflow | C26: A LOT is on Hold | D26: Release the hold as Quality with a Controlled Run Tag disposition | E26: The hold closes, LotStatusCode returns to Good, and Lot.CrtActive is set to 1; the next downstream operation screen forces the 200% double-capture | I26: CRT activate/clear procs built; the 200%-inspect double-capture is view-enforced off getRequiredInspections (not proc-gated) in v1
A27: FAT-PLC-170 | B27: CRT workflow | C27: A CRT-active LOT (CrtActive=1) reaches its next operation | D27: Complete the forced 200% inspection (or skip it) | E27: On completion CrtActive clears (Lot_ClearCrt, supervisor-elevated) with a CrtCompleted result; if the CRT run passed through un-inspected the LOT is flagged for re-run with a MissedCrtInspect hold
A28: FDS-10-006 — OmniServer Scale Reads
A29: FAT-PLC-180 | B29: Scale reads | C29: A ScaleStation instance mapped to an assembly terminal; Sim Panel open | D29: Seed a net weight with MetFlag=False and fire NET_DataReady | E29: The watcher reads NET_NetWeightValue / UOM / TargetWeightMetFlag, acknowledges NET_DataReady, and logs the weigh to Audit.InterfaceLog; no container close occurs | I29: Simulator-validated; raw-weight persistence (a ProductionEvent/QualitySample) is a commissioning fill-in — weight is captured in the InterfaceLog payload only
A30: FAT-PLC-190 | B30: Scale reads | C30: ScaleStation device selected in the Sim Panel | D30: Fire NET_DataReady with MetFlag=True | E30: The scale is coupled to container completion — a ByWeight tray close runs through Assembly_CompleteTray at the configured ByWeight piece count; the container auto-completes (AIM + label) when full | I30: Simulator-validated
A31: FDS-10-007 — Barcode Scanners
A32: FAT-PLC-200 | B32: Barcode scan validation | C32: A plant-floor screen with an active LTT input field | D32: Scan a valid LTT barcode with the terminal's keyboard-wedge scanner | E32: Scan data is injected as keystrokes into the active field (no custom driver); on submit the server validates the LTT format (9-digit + checksum, ufn_IsValidExternalLtt) and accepts it | I32: Witnessable directly; keyboard-wedge behaviour is client-side plus server-side format validation
A33: FAT-PLC-210 | B33: Barcode scan validation | C33: A plant-floor screen with an active LTT input field | D33: Scan a malformed / wrong-format barcode | E33: Server-side format validation rejects the scan with an operator toast; no LOT action is taken
A34: FDS-10-013 — Confirmation Method LocationAttribute
A35: FAT-PLC-220 | B35: Confirmation method | C35: A PLC-integrated assembly Cell | D35: Inspect the Cell's ConfirmationMethod LocationAttribute | E35: The attribute is seeded and readable with an allowed value (Vision / Barcode / Both) declaring which source(s) confirm part identity
A36: FAT-PLC-230 | B36: Confirmation method | C36: A Cell whose ConfirmationMethod = Both | D36: Present a vision read and a barcode read that disagree on part identity | E36: The production event does not record until both sources agree; the mismatch counts toward the line-stop threshold, and a supervisor-elevated manual override logs HardwareInterlockBypassed on the ContainerSerial | I36: Attribute is seeded and read by the proc/UI; the full Both-reconcile enforcement + override path mirrors the FDS-10-005 line-stop and is partly a commissioning fill-in

Sheet Users & Attribution
A1: TestID | B1: Workflow | C1: Precondition | D1: Step | E1: Expected Result | F1: Result | G1: Witness | H1: Date | I1: Notes
A2: FDS-04-001 — Two Identity Classes
A3: FAT-USR-010 | B3: Two identity classes | C3: Config Tool AppUser admin | D3: Create an operator AppUser and an interactive-user AppUser | E3: Operator saved with AdAccount NULL, Initials NOT NULL, no Ignition role; interactive user saved with AdAccount and a role
A4: FAT-USR-020 | B4: Event attribution by AppUserId | C4: Any shop-floor event recorded | D4: Inspect the stored attribution on the event | E4: Event stamps a resolved AppUserId (never free-text initials or names)
A5: FDS-04-002 — Operator Initials Capture
A6: FAT-USR-030 | B6: Operator initials capture | C6: A shop-floor terminal at idle | D6: Approach the terminal and perform a first action | E6: UI prompts for initials; MES resolves the AppUser and establishes an operator presence context; no password is verified
A7: FAT-USR-040 | B7: Presence context handoff | C7: An operator presence context established | D7: Enter a different operator's initials | E7: New presence context replaces the prior one for subsequent events
A8: FDS-04-003 — Presence Policy: Dedicated vs Shared Views
A9: FAT-USR-050 | B9: Dedicated presence policy | C9: A terminal running a dedicated-flavor view | D9: Leave idle then return | E9: policy = confirm; initials persist across idle gaps subject only to the 30-minute re-confirmation
A10: FAT-USR-060 | B10: Shared presence policy | C10: A terminal running a shared-flavor view (e.g. Die Cast cabin) | D10: Return after idle or change the cell context | E10: policy = strict; initials re-requested on first action after idle and re-prompted when the operator changes cell context
A11: FDS-04-004 — Interactive User Authentication
A12: FAT-USR-070 | B12: Interactive user AD auth | C12: An interactive user (Quality/Supervisor/Engineering/Admin) | D12: Log into the Config Tool with AD credentials | E12: Authenticates via Ignition's AD user source; operators do not exist in AD
A13: FDS-04-005 — Pre-Populated Initials Field
A14: FAT-USR-080 | B14: Pre-populated initials field | C14: A mutation screen under an operator presence context | D14: Open a shop-floor mutation form | E14: Initials field is pre-populated from the presence context; operator may override before submit
A15: FAT-USR-090 | B15: Unknown/deprecated initials blocked | C15: A shop-floor mutation form | D15: Submit with unknown or deprecated initials | E15: Submission blocked with a clear message via AppUser_GetByInitials; no auto-creation of users from unknown initials
A16: FDS-04-006 — 30-Minute Presence Re-Confirmation
A17: FAT-USR-100 | B17: 30-minute re-confirmation | C17: A terminal idle longer than 30 minutes | D17: Interact with the terminal | E17: Re-confirmation overlay 'Operate as [XY]?' with [Yes] / [No — change]; Yes continues the context, No opens initials entry and clears the prior context
A18: FAT-USR-110 | B18: Configurable timeout | C18: Config Tool presence-timeout setting | D18: Change the re-confirmation interval | E18: The 30-minute value is a Configuration Tool setting (not hard-coded) and takes effect
A19: FDS-04-007 — Elevated Actions Require Active Directory Authentication
A20: FAT-USR-120 | B20: Per-action AD elevation | C20: A shop-floor terminal with operator presence | D20: Trigger an elevated action (e.g. place hold / scrap) | E20: Elevation prompt accepts AD username+password; on success the action is stamped with the authenticating user's AppUserId, not the operator presence context
A21: FAT-USR-130 | B21: Elevation not session-sticky | C21: An elevated action just completed | D21: Trigger a second elevated action | E21: Each elevated action re-prompts for AD; there is no session-sticky (5-minute) elevation
A22: FAT-USR-140 | B22: Elevation cancel | C22: Elevation prompt open | D22: Cancel the prompt | E22: Action does not execute; UI returns to the prior state
A23: FDS-04-008 — Ignition Role Mapping
A24: FAT-USR-150 | B24: Ignition role mapping | C24: AD groups mapped to Ignition roles | D24: Sign in as each interactive role | E24: Quality / Supervisor / Engineering / Admin capabilities resolve per their AD group; Operator is the absence of interactive authentication
A25: FDS-04-009 — Screen-Level Security
A26: FAT-USR-160 | B26: Screen-level security | C26: Shop-floor and Config Tool screens | D26: Access each without interactive authentication | E26: Shop-floor screens open on operator presence alone and expose no master-data functions; Config Tool / Supervisor / Engineering screens require AD auth on page entry
A27: FAT-USR-170 | B27: Elevated controls visible but gated | C27: A shop-floor screen with elevated action buttons | D27: View and activate an elevated control as an operator | E27: Control is visible but triggers the FDS-04-007 AD prompt on activation; an unauthorised user cancels out
A28: FDS-04-010 — Operator AppUser Lifecycle
A29: FAT-USR-180 | B29: Operator AppUser lifecycle | C29: Admin-only AppUser screen | D29: Create an operator whose initials collide with an existing row | E29: Admin enters disambiguating initials (unique); operator rows carry AdAccount NULL and no Ignition role
A30: FAT-USR-190 | B30: Operator deprecation | C30: An operator AppUser with historical events | D30: Deprecate the operator | E30: Standard DeprecatedAt soft-delete; events referencing the operator retain the historical AppUserId

Sheet Terminal & Login
A1: TestID | B1: Workflow | C1: Precondition | D1: Step | E1: Expected Result | F1: Result | G1: Witness | H1: Date | I1: Notes
A2: FDS-02-008 — Terminal as Cell Kind
A3: FAT-TERM-010 | B3: Terminal registration | C3: Config Tool location admin | D3: Register a shop-floor station as a Terminal Location | E3: Location created with LocationTypeDefinition = Terminal (resolving to LocationType = Cell), parented under a Cell/WorkCenter/Area
A4: FAT-TERM-020 | B4: Terminal attributes | C4: A registered Terminal | D4: Set IP address, default Zebra printer, and scanner-availability attributes | E4: Attributes stored as LocationAttribute entries on the Terminal definition; registry surfaces a HasPrinter validation flag
A5: FAT-TERM-030 | B5: Terminal requires child printer | C5: A Terminal with no active child Printer | D5: Review the terminal registry validation | E5: HasPrinter flag marks the terminal as missing a printer; every Terminal carries at least one active child Printer Location
A6: FAT-TERM-040 | B6: Terminal resolves by IP | C6: A registered terminal | D6: Open a Perspective session from the terminal's IP | E6: Gateway resolver returns terminal identity, parent zone, and DefaultScreen (Terminal_GetByIpAddress) — no mode carried
A7: FDS-02-009 — Cell Context Selection
A8: FAT-TERM-060 | B8: Dedicated cell context | C8: A terminal running a dedicated-flavor view | D8: Start a session | E8: Location context is fixed to the Terminal's parent Location (Cell/Line/Area); no selector shown; events carry both TerminalLocationId and LocationId
A9: FAT-TERM-070 | B9: Shared cell context selection | C9: A terminal running a shared-flavor view (Die Cast cabin) | D9: Start a session and pick the press | E9: Operator selects context by scan or dropdown from the terminal-parent's descendant equipment Cells (Terminal_ListContextCells); chosen LocationId applies to subsequent events
A10: FAT-TERM-080 | B10: Mid-session context change | C10: A shared-flavor terminal with a context selected | D10: Change the cell context by scan or dropdown | E10: New LocationId applies to all subsequent events until changed again
A11: FDS-02-010 — Terminal Behavior Determined by Assigned View
A12: FAT-TERM-090 | B12: View flavor determines behavior | C12: Two terminals with different DefaultScreen assignments | D12: Compare a dedicated-flavor and a shared-flavor terminal | E12: Dedicated-vs-shared behavior follows the assigned operator view (DefaultScreen); no TerminalMode attribute exists; session.custom.presence.policy is set on load
A13: FAT-TERM-100 | B13: DefaultScreen assignment | C13: Config Tool location admin | D13: Attach a Terminal under a tier and assign its DefaultScreen | E13: Terminal can be parented at Cell/WorkCenter/Area; behavior follows the assigned view from the MPP per-workstation list
A14: FDS-02-011 — Cell Context Change Rules
A15: FAT-TERM-110 | B15: Dedicated context locked | C15: A dedicated-flavor terminal | D15: Attempt to change the cell context | E15: No scan/dropdown/search is offered; the parent Location is the fixed context for the session
A16: FAT-TERM-120 | B16: Shared context change constrained | C16: A shared-flavor terminal | D16: Change context via the selector | E16: Change is allowed only via scan-or-dropdown, constrained to descendant equipment Cells of the terminal's parent (prevents cross-machine misattribution)
A17: FDS-02-012 — Part ↔ Cell Eligibility
A18: FAT-TERM-130 | B18: Part↔Cell eligibility — direct | C18: A LOT being scanned into a cell | D18: Scan a LOT whose Item has direct ItemLocation eligibility at the cell or an ancestor tier | E18: Scan-in passes the eligibility check (ItemLocation_CheckEligibility)
A19: FAT-TERM-140 | B19: Part↔Cell eligibility — BOM-derived | C19: A component LOT at an assembly cell | D19: Scan a LOT that is a child line of an eligible parent's active BOM | E19: Scan-in passes via BOM-derived eligibility (no explicit ItemLocation row required)
